Workbook

Sheet きゅうり
A1: 1．「きゅうり」の卸売数量と価格の推移 | K1: =TEXT(集計表!$C$1,"(e.m/d～)") -> (8.6/1～)
A2: （東京都中央卸売市場）
AI20: 260
A35: =集計表!C1 -> 46174 | B35: =集計表!D1 -> 6/1 | C35: =集計表!E1 -> 2 | D35: =集計表!F1 -> 4 | E35: =集計表!G1 -> 5 | F35: =集計表!H1 -> 6 | G35: =集計表!I1 -> 8 | H35: =集計表!J1 -> 9 | ... AR35: =集計表!AT1 -> 31
A36: 入荷量 | B36: =IF(集計表!D3="","",集計表!D3) -> 364.892 | C36: =IF(集計表!E3="","",集計表!E3) -> 215.789 | D36: =IF(集計表!F3="","",集計表!F3) -> 331.685 | E36: =IF(集計表!G3="","",集計表!G3) -> 178.3 | F36: =IF(集計表!H3="","",集計表!H3) -> 158.549 | G36: =IF(集計表!I3="","",集計表!I3) -> 269.682 | H36: =IF(集計表!J3="","",集計表!J3) -> 185.025 | I36: =IF(集計表!K3="","",集計表!K3) -> 300.016 | ... AR36: =IF(集計表!AT3="","",集計表!AT3)
A37: 卸売価格 | B37: =IF(集計表!D4=0,NA(),集計表!D4) -> 255 | C37: =IF(集計表!E4=0,NA(),集計表!E4) -> 256 | D37: =IF(集計表!F4=0,NA(),集計表!F4) -> 254 | E37: =IF(集計表!G4=0,NA(),集計表!G4) -> 266 | F37: =IF(集計表!H4=0,NA(),集計表!H4) -> 295 | G37: =IF(集計表!I4=0,NA(),集計表!I4) -> 332 | H37: =IF(集計表!J4=0,NA(),集計表!J4) -> 347 | I37: =IF(集計表!K4=0,NA(),集計表!K4) -> 349 | ... AR37: =IF(集計表!AT4=0,NA(),集計表!AT4) -> #N/A
A38: 平均価格 | B38: =集計表!D5 -> 268 | C38: =集計表!E5 -> 268 | D38: =集計表!F5 -> 268 | E38: =集計表!G5 -> 268 | F38: =集計表!H5 -> 268 | G38: =集計表!I5 -> 268 | H38: =集計表!J5 -> 268 | I38: =集計表!K5 -> 261 | ... AR38: =集計表!AT5 -> 291
A39: 平年比 | B39: =IFERROR(B37/B38, "") -> 0.95149254 | C39: =IFERROR(C37/C38, "") -> 0.95522388 | D39: =IFERROR(D37/D38, "") -> 0.94776119 | E39: =IFERROR(E37/E38, "") -> 0.99253731 | F39: =IFERROR(F37/F38, "") -> 1.1007463 | G39: =IFERROR(G37/G38, "") -> 1.238806 | H39: =IFERROR(H37/H38, "") -> 1.2947761 | I39: =IFERROR(I37/I38, "") -> 1.3371648 | ... AR39: =IFERROR(AR37/AR38, "")
A40: 資料：alic「ベジ探」、（原資料）農林水産省「青果物卸売市場調査（日別調査）結果」
A41: 1．「きゅうり」の卸売数量と価格の推移 | K41: =TEXT(集計表!$C$1,"(e.m/d～)") -> (8.6/1～)
A42: （名古屋市中央卸売市場）
A75: =集計表!C7 -> 46174 | B75: =集計表!D7 -> 6/1 | C75: =集計表!E7 -> 2 | D75: =集計表!F7 -> 4 | E75: =集計表!G7 -> 5 | F75: =集計表!H7 -> 6 | G75: =集計表!I7 -> 8 | H75: =集計表!J7 -> 9 | ... AR75: =集計表!AT7 -> 31
A76: 入荷量 | B76: =IF(集計表!D9="","",集計表!D9) -> 84.773 | C76: =IF(集計表!E9="","",集計表!E9) -> 72.381 | D76: =IF(集計表!F9="","",集計表!F9) -> 79.922 | E76: =IF(集計表!G9="","",集計表!G9) -> 50.75 | F76: =IF(集計表!H9="","",集計表!H9) -> 57.715 | G76: =IF(集計表!I9="","",集計表!I9) -> 66.613 | H76: =IF(集計表!J9="","",集計表!J9) -> 60.658 | I76: =IF(集計表!K9="","",集計表!K9) -> 64.84 | ... AR76: =IF(集計表!AT9="","",集計表!AT9)
A77: 卸売価格 | B77: =IF(集計表!D10=0,NA(),集計表!D10) -> 292 | C77: =IF(集計表!E10=0,NA(),集計表!E10) -> 278 | D77: =IF(集計表!F10=0,NA(),集計表!F10) -> 275 | E77: =IF(集計表!G10=0,NA(),集計表!G10) -> 289 | F77: =IF(集計表!H10=0,NA(),集計表!H10) -> 307 | G77: =IF(集計表!I10=0,NA(),集計表!I10) -> 310 | H77: =IF(集計表!J10=0,NA(),集計表!J10) -> 332 | I77: =IF(集計表!K10=0,NA(),集計表!K10) -> 312 | ... AR77: =IF(集計表!AT10=0,NA(),集計表!AT10) -> #N/A
A78: 平均価格 | B78: =集計表!D11 -> 269 | C78: =集計表!E11 -> 269 | D78: =集計表!F11 -> 269 | E78: =集計表!G11 -> 269 | F78: =集計表!H11 -> 269 | G78: =集計表!I11 -> 269 | H78: =集計表!J11 -> 269 | I78: =集計表!K11 -> 271 | ... AR78: =集計表!AT11 -> 308
A79: 平年比 | B79: =IFERROR(B77/B78, "") -> 1.0855019 | C79: =IFERROR(C77/C78, "") -> 1.0334572 | D79: =IFERROR(D77/D78, "") -> 1.0223048 | E79: =IFERROR(E77/E78, "") -> 1.0743494 | F79: =IFERROR(F77/F78, "") -> 1.1412639 | G79: =IFERROR(G77/G78, "") -> 1.1524164 | H79: =IFERROR(H77/H78, "") -> 1.2342007 | I79: =IFERROR(I77/I78, "") -> 1.1512915 | ... AR79: =IFERROR(AR77/AR78, "")
A80: 資料：alic「ベジ探」、（原資料）農林水産省「青果物卸売市場調査（日別調査）結果」
A81: 1．「きゅうり」の卸売数量と価格の推移 | K81: =TEXT(集計表!$C$1,"(e.m/d～)") -> (8.6/1～)
A82: （大阪市中央卸売市場）
A115: =集計表!C13 -> 46174 | B115: =集計表!D13 -> 6/1 | C115: =集計表!E13 -> 2 | D115: =集計表!F13 -> 4 | E115: =集計表!G13 -> 5 | F115: =集計表!H13 -> 6 | G115: =集計表!I13 -> 8 | H115: =集計表!J13 -> 9 | ... AR115: =集計表!AT13 -> 31
A116: 入荷量 | B116: =IF(集計表!D15="","",集計表!D15) -> 85.244 | C116: =IF(集計表!E15="","",集計表!E15) -> 50.196 | D116: =IF(集計表!F15="","",集計表!F15) -> 77.613 | E116: =IF(集計表!G15="","",集計表!G15) -> 42.025 | F116: =IF(集計表!H15="","",集計表!H15) -> 56.294 | G116: =IF(集計表!I15="","",集計表!I15) -> 72.8 | H116: =IF(集計表!J15="","",集計表!J15) -> 48.997 | I116: =IF(集計表!K15="","",集計表!K15) -> 56.929 | ... AR116: =IF(集計表!AT15="","",集計表!AT15)
A117: 卸売価格 | B117: =IF(集計表!D16=0,NA(),集計表!D16) -> 241 | C117: =IF(集計表!E16=0,NA(),集計表!E16) -> 256 | D117: =IF(集計表!F16=0,NA(),集計表!F16) -> 250 | E117: =IF(集計表!G16=0,NA(),集計表!G16) -> 278 | F117: =IF(集計表!H16=0,NA(),集計表!H16) -> 265 | G117: =IF(集計表!I16=0,NA(),集計表!I16) -> 295 | H117: =IF(集計表!J16=0,NA(),集計表!J16) -> 337 | I117: =IF(集計表!K16=0,NA(),集計表!K16) -> 324 | ... AR117: =IF(集計表!AT16=0,NA(),集計表!AT16) -> #N/A
A118: 平均価格 | B118: =集計表!D17 -> 252 | C118: =集計表!E17 -> 252 | D118: =集計表!F17 -> 252 | E118: =集計表!G17 -> 252 | F118: =集計表!H17 -> 252 | G118: =集計表!I17 -> 252 | H118: =集計表!J17 -> 252 | I118: =集計表!K17 -> 258 | ... AR118: =集計表!AT17 -> 298
A119: 平年比 | B119: =IFERROR(B117/B118, "") -> 0.95634921 | C119: =IFERROR(C117/C118, "") -> 1.015873 | D119: =IFERROR(D117/D118, "") -> 0.99206349 | E119: =IFERROR(E117/E118, "") -> 1.1031746 | F119: =IFERROR(F117/F118, "") -> 1.0515873 | G119: =IFERROR(G117/G118, "") -> 1.1706349 | H119: =IFERROR(H117/H118, "") -> 1.3373016 | I119: =IFERROR(I117/I118, "") -> 1.255814 | ... AR119: =IFERROR(AR117/AR118, "")
A120: 資料：alic「ベジ探」、（原資料）農林水産省「青果物卸売市場調査（日別調査）結果」
A121: 1．「きゅうり」の卸売数量と価格の推移 | K121: =TEXT(集計表!$C$1,"(e.m/d～)") -> (8.6/1～)
A122: （福岡市中央卸売市場）
A155: =集計表!C19 -> 46174 | B155: =集計表!D19 -> 6/1 | C155: =集計表!E19 -> 2 | D155: =集計表!F19 -> 4 | E155: =集計表!G19 -> 5 | F155: =集計表!H19 -> 6 | G155: =集計表!I19 -> 8 | H155: =集計表!J19 -> 9 | ... AR155: =集計表!AT19 -> 31
A156: 入荷量 | B156: =IF(集計表!D21="","",集計表!D21) -> 64.113 | C156: =IF(集計表!E21="","",集計表!E21) -> 59.839 | D156: =IF(集計表!F21="","",集計表!F21) -> 74.663 | E156: =IF(集計表!G21="","",集計表!G21) -> 41.733 | F156: =IF(集計表!H21="","",集計表!H21) -> 45.334 | G156: =IF(集計表!I21="","",集計表!I21) -> 59.483 | H156: =IF(集計表!J21="","",集計表!J21) -> 60.132 | I156: =IF(集計表!K21="","",集計表!K21) -> 65.485 | ... AR156: =IF(集計表!AT21="","",集計表!AT21)
A157: 卸売価格 | B157: =IF(集計表!D22=0,NA(),集計表!D22) -> 214 | C157: =IF(集計表!E22=0,NA(),集計表!E22) -> 227 | D157: =IF(集計表!F22=0,NA(),集計表!F22) -> 233 | E157: =IF(集計表!G22=0,NA(),集計表!G22) -> 247 | F157: =IF(集計表!H22=0,NA(),集計表!H22) -> 255 | G157: =IF(集計表!I22=0,NA(),集計表!I22) -> 277 | H157: =IF(集計表!J22=0,NA(),集計表!J22) -> 277 | I157: =IF(集計表!K22=0,NA(),集計表!K22) -> 294 | ... AR157: =IF(集計表!AT22=0,NA(),集計表!AT22) -> #N/A
A158: 平均価格 | B158: =集計表!D23 -> 214 | C158: =集計表!E23 -> 214 | D158: =集計表!F23 -> 214 | E158: =集計表!G23 -> 214 | F158: =集計表!H23 -> 214 | G158: =集計表!I23 -> 214 | H158: =集計表!J23 -> 214 | I158: =集計表!K23 -> 198 | ... AR158: =集計表!AT23 -> 303
A159: 平年比 | B159: =IFERROR(B157/B158, "") -> 1 | C159: =IFERROR(C157/C158, "") -> 1.0607477 | D159: =IFERROR(D157/D158, "") -> 1.088785 | E159: =IFERROR(E157/E158, "") -> 1.1542056 | F159: =IFERROR(F157/F158, "") -> 1.1915888 | G159: =IFERROR(G157/G158, "") -> 1.2943925 | H159: =IFERROR(H157/H158, "") -> 1.2943925 | I159: =IFERROR(I157/I158, "") -> 1.4848485 | ... AR159: =IFERROR(AR157/AR158, "")
A160: 資料：alic「ベジ探」、（原資料）農林水産省「青果物卸売市場調査（日別調査）結果」

Sheet トマト
A1: ２．「トマト」の卸売数量と価格の推移 | K1: =TEXT(集計表!$C$1,"(e.m/d～)") -> (8.6/1～)
A2: （東京都中央卸売市場）
A35: =集計表!C27 -> 46174 | B35: =集計表!D27 -> 6/1 | C35: =集計表!E27 -> 2 | D35: =集計表!F27 -> 4 | E35: =集計表!G27 -> 5 | F35: =集計表!H27 -> 6 | G35: =集計表!I27 -> 8 | H35: =集計表!J27 -> 9 | ... AR35: =集計表!AT27 -> 31
A36: 入荷量 | B36: =IF(集計表!D29="","",集計表!D29) -> 309.851 | C36: =IF(集計表!E29="","",集計表!E29) -> 201.732 | D36: =IF(集計表!F29="","",集計表!F29) -> 371.897 | E36: =IF(集計表!G29="","",集計表!G29) -> 199.208 | F36: =IF(集計表!H29="","",集計表!H29) -> 286.082 | G36: =IF(集計表!I29="","",集計表!I29) -> 357.158 | H36: =IF(集計表!J29="","",集計表!J29) -> 229.15 | I36: =IF(集計表!K29="","",集計表!K29) -> 347.238 | ... AR36: =IF(集計表!AT29="","",集計表!AT29)
A37: 卸売価格 | B37: =IF(集計表!D30=0,NA(),集計表!D30) -> 390 | C37: =IF(集計表!E30=0,NA(),集計表!E30) -> 404 | D37: =IF(集計表!F30=0,NA(),集計表!F30) -> 402 | E37: =IF(集計表!G30=0,NA(),集計表!G30) -> 402 | F37: =IF(集計表!H30=0,NA(),集計表!H30) -> 417 | G37: =IF(集計表!I30=0,NA(),集計表!I30) -> 398 | H37: =IF(集計表!J30=0,NA(),集計表!J30) -> 403 | I37: =IF(集計表!K30=0,NA(),集計表!K30) -> 406 | ... AR37: =IF(集計表!AT30=0,NA(),集計表!AT30) -> #N/A
A38: 平均価格 | B38: =集計表!D31 -> 317 | C38: =集計表!E31 -> 317 | D38: =集計表!F31 -> 317 | E38: =集計表!G31 -> 317 | F38: =集計表!H31 -> 317 | G38: =集計表!I31 -> 317 | H38: =集計表!J31 -> 317 | I38: =集計表!K31 -> 351 | ... AR38: =集計表!AT31 -> 374
A39: 平年比 | B39: =IFERROR(B37/B38, "") -> 1.2302839 | C39: =IFERROR(C37/C38, "") -> 1.2744479 | D39: =IFERROR(D37/D38, "") -> 1.2681388 | E39: =IFERROR(E37/E38, "") -> 1.2681388 | F39: =IFERROR(F37/F38, "") -> 1.3154574 | G39: =IFERROR(G37/G38, "") -> 1.2555205 | H39: =IFERROR(H37/H38, "") -> 1.2712934 | I39: =IFERROR(I37/I38, "") -> 1.1566952 | ... AR39: =IFERROR(AR37/AR38, "")
A40: 資料：alic「ベジ探」、（原資料）農林水産省「青果物卸売市場調査（日別調査）結果」
A41: =A1 -> ２．「トマト」の卸売数量と価格の推移 | K41: =TEXT(集計表!$C$1,"(e.m/d～)") -> (8.6/1～)
A42: （名古屋市中央卸売市場）
A75: =集計表!C33 -> 46174 | B75: =集計表!D33 -> 6/1 | C75: =集計表!E33 -> 2 | D75: =集計表!F33 -> 4 | E75: =集計表!G33 -> 5 | F75: =集計表!H33 -> 6 | G75: =集計表!I33 -> 8 | H75: =集計表!J33 -> 9 | ... AR75: =集計表!AT33 -> 31
A76: 入荷量 | B76: =IF(集計表!D35="","",集計表!D35) -> 92.629 | C76: =IF(集計表!E35="","",集計表!E35) -> 58.246 | D76: =IF(集計表!F35="","",集計表!F35) -> 105.395 | E76: =IF(集計表!G35="","",集計表!G35) -> 59.839 | F76: =IF(集計表!H35="","",集計表!H35) -> 70.196 | G76: =IF(集計表!I35="","",集計表!I35) -> 93.37 | H76: =IF(集計表!J35="","",集計表!J35) -> 56.257 | I76: =IF(集計表!K35="","",集計表!K35) -> 81.138 | ... AR76: =IF(集計表!AT35="","",集計表!AT35)
A77: 卸売価格 | B77: =IF(集計表!D36=0,NA(),集計表!D36) -> 330 | C77: =IF(集計表!E36=0,NA(),集計表!E36) -> 337 | D77: =IF(集計表!F36=0,NA(),集計表!F36) -> 330 | E77: =IF(集計表!G36=0,NA(),集計表!G36) -> 335 | F77: =IF(集計表!H36=0,NA(),集計表!H36) -> 341 | G77: =IF(集計表!I36=0,NA(),集計表!I36) -> 333 | H77: =IF(集計表!J36=0,NA(),集計表!J36) -> 348 | I77: =IF(集計表!K36=0,NA(),集計表!K36) -> 343 | ... AR77: =IF(集計表!AT36=0,NA(),集計表!AT36) -> #N/A
A78: 平均価格 | B78: =集計表!D37 -> 269 | C78: =集計表!E37 -> 269 | D78: =集計表!F37 -> 269 | E78: =集計表!G37 -> 269 | F78: =集計表!H37 -> 269 | G78: =集計表!I37 -> 269 | H78: =集計表!J37 -> 269 | I78: =集計表!K37 -> 294 | ... AR78: =集計表!AT37 -> 367
A79: 平年比 | B79: =IFERROR(B77/B78, "") -> 1.2267658 | C79: =IFERROR(C77/C78, "") -> 1.2527881 | D79: =IFERROR(D77/D78, "") -> 1.2267658 | E79: =IFERROR(E77/E78, "") -> 1.2453532 | F79: =IFERROR(F77/F78, "") -> 1.267658 | G79: =IFERROR(G77/G78, "") -> 1.2379182 | H79: =IFERROR(H77/H78, "") -> 1.2936803 | I79: =IFERROR(I77/I78, "") -> 1.1666667 | ... AR79: =IFERROR(AR77/AR78, "")
A80: 資料：alic「ベジ探」、（原資料）農林水産省「青果物卸売市場調査（日別調査）結果」
A81: =A1 -> ２．「トマト」の卸売数量と価格の推移 | K81: =TEXT(集計表!$C$1,"(e.m/d～)") -> (8.6/1～)
A82: （大阪市中央卸売市場）
A115: =集計表!C39 -> 46174 | B115: =集計表!D39 -> 6/1 | C115: =集計表!E39 -> 2 | D115: =集計表!F39 -> 4 | E115: =集計表!G39 -> 5 | F115: =集計表!H39 -> 6 | G115: =集計表!I39 -> 8 | H115: =集計表!J39 -> 9 | ... AR115: =集計表!AT39 -> 31
A116: 入荷量 | B116: =IF(集計表!D41="","",集計表!D41) -> 116.022 | C116: =IF(集計表!E41="","",集計表!E41) -> 70.417 | D116: =IF(集計表!F41="","",集計表!F41) -> 112.553 | E116: =IF(集計表!G41="","",集計表!G41) -> 68.597 | F116: =IF(集計表!H41="","",集計表!H41) -> 79.708 | G116: =IF(集計表!I41="","",集計表!I41) -> 134.476 | H116: =IF(集計表!J41="","",集計表!J41) -> 72.179 | I116: =IF(集計表!K41="","",集計表!K41) -> 115.647 | ... AR116: =IF(集計表!AT41="","",集計表!AT41)
A117: 卸売価格 | B117: =IF(集計表!D42=0,NA(),集計表!D42) -> 363 | C117: =IF(集計表!E42=0,NA(),集計表!E42) -> 374 | D117: =IF(集計表!F42=0,NA(),集計表!F42) -> 368 | E117: =IF(集計表!G42=0,NA(),集計表!G42) -> 368 | F117: =IF(集計表!H42=0,NA(),集計表!H42) -> 383 | G117: =IF(集計表!I42=0,NA(),集計表!I42) -> 363 | H117: =IF(集計表!J42=0,NA(),集計表!J42) -> 374 | I117: =IF(集計表!K42=0,NA(),集計表!K42) -> 367 | ... AR117: =IF(集計表!AT42=0,NA(),集計表!AT42) -> #N/A
A118: 平均価格 | B118: =集計表!D43 -> 311 | C118: =集計表!E43 -> 311 | D118: =集計表!F43 -> 311 | E118: =集計表!G43 -> 311 | F118: =集計表!H43 -> 311 | G118: =集計表!I43 -> 311 | H118: =集計表!J43 -> 311 | I118: =集計表!K43 -> 333 | ... AR118: =集計表!AT43 -> 361
A119: 平年比 | B119: =IFERROR(B117/B118, "") -> 1.1672026 | C119: =IFERROR(C117/C118, "") -> 1.2025723 | D119: =IFERROR(D117/D118, "") -> 1.1832797 | E119: =IFERROR(E117/E118, "") -> 1.1832797 | F119: =IFERROR(F117/F118, "") -> 1.2315113 | G119: =IFERROR(G117/G118, "") -> 1.1672026 | H119: =IFERROR(H117/H118, "") -> 1.2025723 | I119: =IFERROR(I117/I118, "") -> 1.1021021 | ... AR119: =IFERROR(AR117/AR118, "")
A120: 資料：alic「ベジ探」、（原資料）農林水産省「青果物卸売市場調査（日別調査）結果」
A121: =A1 -> ２．「トマト」の卸売数量と価格の推移 | J121: =TEXT(集計表!$C$1,"(e.m/d～)") -> (8.6/1～)
A122: （福岡市中央卸売市場）
A155: =集計表!C45 -> 46174 | B155: =集計表!D45 -> 6/1 | C155: =集計表!E45 -> 2 | D155: =集計表!F45 -> 4 | E155: =集計表!G45 -> 5 | F155: =集計表!H45 -> 6 | G155: =集計表!I45 -> 8 | H155: =集計表!J45 -> 9 | ... AR155: =集計表!AT45 -> 31
A156: 入荷量 | B156: =IF(集計表!D47="","",集計表!D47) -> 38.659 | C156: =IF(集計表!E47="","",集計表!E47) -> 41.556 | D156: =IF(集計表!F47="","",集計表!F47) -> 48.404 | E156: =IF(集計表!G47="","",集計表!G47) -> 35.673 | F156: =IF(集計表!H47="","",集計表!H47) -> 44.64 | G156: =IF(集計表!I47="","",集計表!I47) -> 57.393 | H156: =IF(集計表!J47="","",集計表!J47) -> 45.831 | I156: =IF(集計表!K47="","",集計表!K47) -> 57.936 | ... AR156: =IF(集計表!AT47="","",集計表!AT47)
A157: 卸売価格 | B157: =IF(集計表!D48=0,NA(),集計表!D48) -> 342 | C157: =IF(集計表!E48=0,NA(),集計表!E48) -> 342 | D157: =IF(集計表!F48=0,NA(),集計表!F48) -> 344 | E157: =IF(集計表!G48=0,NA(),集計表!G48) -> 351 | F157: =IF(集計表!H48=0,NA(),集計表!H48) -> 348 | G157: =IF(集計表!I48=0,NA(),集計表!I48) -> 325 | H157: =IF(集計表!J48=0,NA(),集計表!J48) -> 324 | I157: =IF(集計表!K48=0,NA(),集計表!K48) -> 319 | ... AR157: =IF(集計表!AT48=0,NA(),集計表!AT48) -> #N/A
A158: 平均価格 | B158: =集計表!D49 -> 260 | C158: =集計表!E49 -> 260 | D158: =集計表!F49 -> 260 | E158: =集計表!G49 -> 260 | F158: =集計表!H49 -> 260 | G158: =集計表!I49 -> 260 | H158: =集計表!J49 -> 260 | I158: =集計表!K49 -> 273 | ... AR158: =集計表!AT49 -> 292
A159: 平年比 | B159: =IFERROR(B157/B158, "") -> 1.3153846 | C159: =IFERROR(C157/C158, "") -> 1.3153846 | D159: =IFERROR(D157/D158, "") -> 1.3230769 | E159: =IFERROR(E157/E158, "") -> 1.35 | F159: =IFERROR(F157/F158, "") -> 1.3384615 | G159: =IFERROR(G157/G158, "") -> 1.25 | H159: =IFERROR(H157/H158, "") -> 1.2461538 | I159: =IFERROR(I157/I158, "") -> 1.1684982 | ... AR159: =IFERROR(AR157/AR158, "")
A160: 資料：alic「ベジ探」、（原資料）農林水産省「青果物卸売市場調査（日別調査）結果」

Sheet なす
A1: ３．「なす」の卸売数量と価格の推移 | K1: =TEXT(集計表!$C$1,"(e.m/d～)") -> (8.6/1～)
A2: （東京都中央卸売市場）
A35: =集計表!C53 -> 46174 | B35: =集計表!D53 -> 6/1 | C35: =集計表!E53 -> 2 | D35: =集計表!F53 -> 4 | E35: =集計表!G53 -> 5 | F35: =集計表!H53 -> 6 | G35: =集計表!I53 -> 8 | H35: =集計表!J53 -> 9 | ... AR35: =集計表!AT53 -> 31
A36: 入荷量 | B36: =IF(集計表!D55="","",集計表!D55) -> 187.58 | C36: =IF(集計表!E55="","",集計表!E55) -> 117.99 | D36: =IF(集計表!F55="","",集計表!F55) -> 190.325 | E36: =IF(集計表!G55="","",集計表!G55) -> 136.873 | F36: =IF(集計表!H55="","",集計表!H55) -> 115.584 | G36: =IF(集計表!I55="","",集計表!I55) -> 182.774 | H36: =IF(集計表!J55="","",集計表!J55) -> 110.63 | I36: =IF(集計表!K55="","",集計表!K55) -> 191.333 | ... AR36: =IF(集計表!AT55="","",集計表!AT55)
A37: 卸売価格 | B37: =IF(集計表!D56=0,NA(),集計表!D56) -> 389 | C37: =IF(集計表!E56=0,NA(),集計表!E56) -> 392 | D37: =IF(集計表!F56=0,NA(),集計表!F56) -> 393 | E37: =IF(集計表!G56=0,NA(),集計表!G56) -> 395 | F37: =IF(集計表!H56=0,NA(),集計表!H56) -> 409 | G37: =IF(集計表!I56=0,NA(),集計表!I56) -> 426 | H37: =IF(集計表!J56=0,NA(),集計表!J56) -> 446 | I37: =IF(集計表!K56=0,NA(),集計表!K56) -> 437 | ... AR37: =IF(集計表!AT56=0,NA(),集計表!AT56) -> #N/A
A38: 平均価格 | B38: =集計表!D57 -> 401 | C38: =集計表!E57 -> 401 | D38: =集計表!F57 -> 401 | E38: =集計表!G57 -> 401 | F38: =集計表!H57 -> 401 | G38: =集計表!I57 -> 401 | H38: =集計表!J57 -> 401 | I38: =集計表!K57 -> 397 | ... AR38: =集計表!AT57 -> 341
A39: 平年比 | B39: =IFERROR(B37/B38, "") -> 0.97007481 | C39: =IFERROR(C37/C38, "") -> 0.97755611 | D39: =IFERROR(D37/D38, "") -> 0.98004988 | E39: =IFERROR(E37/E38, "") -> 0.98503741 | F39: =IFERROR(F37/F38, "") -> 1.0199501 | G39: =IFERROR(G37/G38, "") -> 1.0623441 | H39: =IFERROR(H37/H38, "") -> 1.1122195 | I39: =IFERROR(I37/I38, "") -> 1.1007557 | ... AR39: =IFERROR(AR37/AR38, "")
A40: 資料：alic「ベジ探」、（原資料）農林水産省「青果物卸売市場調査（日別調査）結果」
A41: ３．「なす」の卸売数量と価格の推移 | K41: =TEXT(集計表!$C$1,"(e.m/d～)") -> (8.6/1～)
A42: （名古屋市中央卸売市場）
A75: =集計表!C59 -> 46174 | B75: =集計表!D59 -> 6/1 | C75: =集計表!E59 -> 2 | D75: =集計表!F59 -> 4 | E75: =集計表!G59 -> 5 | F75: =集計表!H59 -> 6 | G75: =集計表!I59 -> 8 | H75: =集計表!J59 -> 9 | ... AR75: =集計表!AT59 -> 31
A76: 入荷量 | B76: =IF(集計表!D61="","",集計表!D61) -> 48.725 | C76: =IF(集計表!E61="","",集計表!E61) -> 25.543 | D76: =IF(集計表!F61="","",集計表!F61) -> 59.008 | E76: =IF(集計表!G61="","",集計表!G61) -> 32.648 | F76: =IF(集計表!H61="","",集計表!H61) -> 34.409 | G76: =IF(集計表!I61="","",集計表!I61) -> 51.723 | H76: =IF(集計表!J61="","",集計表!J61) -> 24.448 | I76: =IF(集計表!K61="","",集計表!K61) -> 48.944 | ... AR76: =IF(集計表!AT61="","",集計表!AT61)
A77: 卸売価格 | B77: =IF(集計表!D62=0,NA(),集計表!D62) -> 369 | C77: =IF(集計表!E62=0,NA(),集計表!E62) -> 362 | D77: =IF(集計表!F62=0,NA(),集計表!F62) -> 367 | E77: =IF(集計表!G62=0,NA(),集計表!G62) -> 369 | F77: =IF(集計表!H62=0,NA(),集計表!H62) -> 370 | G77: =IF(集計表!I62=0,NA(),集計表!I62) -> 372 | H77: =IF(集計表!J62=0,NA(),集計表!J62) -> 375 | I77: =IF(集計表!K62=0,NA(),集計表!K62) -> 377 | ... AR77: =IF(集計表!AT62=0,NA(),集計表!AT62) -> #N/A
A78: 平均価格 | B78: =集計表!D63 -> 360 | C78: =集計表!E63 -> 360 | D78: =集計表!F63 -> 360 | E78: =集計表!G63 -> 360 | F78: =集計表!H63 -> 360 | G78: =集計表!I63 -> 360 | H78: =集計表!J63 -> 360 | I78: =集計表!K63 -> 369 | ... AR78: =集計表!AT63 -> 328
A79: 平年比 | B79: =IFERROR(B77/B78, "") -> 1.025 | C79: =IFERROR(C77/C78, "") -> 1.0055556 | D79: =IFERROR(D77/D78, "") -> 1.0194444 | E79: =IFERROR(E77/E78, "") -> 1.025 | F79: =IFERROR(F77/F78, "") -> 1.0277778 | G79: =IFERROR(G77/G78, "") -> 1.0333333 | H79: =IFERROR(H77/H78, "") -> 1.0416667 | I79: =IFERROR(I77/I78, "") -> 1.0216802 | ... AR79: =IFERROR(AR77/AR78, "")
A80: 資料：alic「ベジ探」、（原資料）農林水産省「青果物卸売市場調査（日別調査）結果」
A81: ３．「なす」の卸売数量と価格の推移 | K81: =TEXT(集計表!$C$1,"(e.m/d～)") -> (8.6/1～)
A82: （大阪市中央卸売市場）
A115: =集計表!C65 -> 46174 | B115: =集計表!D65 -> 6/1 | C115: =集計表!E65 -> 2 | D115: =集計表!F65 -> 4 | E115: =集計表!G65 -> 5 | F115: =集計表!H65 -> 6 | G115: =集計表!I65 -> 8 | H115: =集計表!J65 -> 9 | ... AR115: =集計表!AT65 -> 31
A116: 入荷量 | B116: =IF(集計表!D67="","",集計表!D67) -> 65.852 | C116: =IF(集計表!E67="","",集計表!E67) -> 51.67 | D116: =IF(集計表!F67="","",集計表!F67) -> 72.381 | E116: =IF(集計表!G67="","",集計表!G67) -> 33.043 | F116: =IF(集計表!H67="","",集計表!H67) -> 47.832 | G116: =IF(集計表!I67="","",集計表!I67) -> 56.841 | H116: =IF(集計表!J67="","",集計表!J67) -> 49.89 | I116: =IF(集計表!K67="","",集計表!K67) -> 63.956 | ... AR116: =IF(集計表!AT67="","",集計表!AT67)
A117: 卸売価格 | B117: =IF(集計表!D68=0,NA(),集計表!D68) -> 369 | C117: =IF(集計表!E68=0,NA(),集計表!E68) -> 319 | D117: =IF(集計表!F68=0,NA(),集計表!F68) -> 354 | E117: =IF(集計表!G68=0,NA(),集計表!G68) -> 377 | F117: =IF(集計表!H68=0,NA(),集計表!H68) -> 346 | G117: =IF(集計表!I68=0,NA(),集計表!I68) -> 386 | H117: =IF(集計表!J68=0,NA(),集計表!J68) -> 387 | I117: =IF(集計表!K68=0,NA(),集計表!K68) -> 370 | ... AR117: =IF(集計表!AT68=0,NA(),集計表!AT68) -> #N/A
A118: 平均価格 | B118: =集計表!D69 -> 366 | C118: =集計表!E69 -> 366 | D118: =集計表!F69 -> 366 | E118: =集計表!G69 -> 366 | F118: =集計表!H69 -> 366 | G118: =集計表!I69 -> 366 | H118: =集計表!J69 -> 366 | I118: =集計表!K69 -> 359 | ... AR118: =集計表!AT69 -> 332
A119: 平年比 | B119: =IFERROR(B117/B118, "") -> 1.0081967 | C119: =IFERROR(C117/C118, "") -> 0.8715847 | D119: =IFERROR(D117/D118, "") -> 0.96721311 | E119: =IFERROR(E117/E118, "") -> 1.0300546 | F119: =IFERROR(F117/F118, "") -> 0.94535519 | G119: =IFERROR(G117/G118, "") -> 1.0546448 | H119: =IFERROR(H117/H118, "") -> 1.057377 | I119: =IFERROR(I117/I118, "") -> 1.0306407 | ... AR119: =IFERROR(AR117/AR118, "")
A120: 資料：alic「ベジ探」、（原資料）農林水産省「青果物卸売市場調査（日別調査）結果」
A121: ３．「なす」の卸売数量と価格の推移 | K121: =TEXT(集計表!$C$1,"(e.m/d～)") -> (8.6/1～)
A122: （福岡市中央卸売市場）
A155: =集計表!C71 -> 46174 | B155: =集計表!D71 -> 6/1 | C155: =集計表!E71 -> 2 | D155: =集計表!F71 -> 4 | E155: =集計表!G71 -> 5 | F155: =集計表!H71 -> 6 | G155: =集計表!I71 -> 8 | H155: =集計表!J71 -> 9 | ... AR155: =集計表!AT71 -> 31
A156: 入荷量 | B156: =IF(集計表!D73="","",集計表!D73) -> 24.914 | C156: =IF(集計表!E73="","",集計表!E73) -> 29.205 | D156: =IF(集計表!F73="","",集計表!F73) -> 37.068 | E156: =IF(集計表!G73="","",集計表!G73) -> 18.451 | F156: =IF(集計表!H73="","",集計表!H73) -> 27.095 | G156: =IF(集計表!I73="","",集計表!I73) -> 25.073 | H156: =IF(集計表!J73="","",集計表!J73) -> 28.499 | I156: =IF(集計表!K73="","",集計表!K73) -> 35.193 | ... AR156: =IF(集計表!AT73="","",集計表!AT73)
A157: 卸売価格 | B157: =IF(集計表!D74=0,NA(),集計表!D74) -> 375 | C157: =IF(集計表!E74=0,NA(),集計表!E74) -> 380 | D157: =IF(集計表!F74=0,NA(),集計表!F74) -> 373 | E157: =IF(集計表!G74=0,NA(),集計表!G74) -> 363 | F157: =IF(集計表!H74=0,NA(),集計表!H74) -> 372 | G157: =IF(集計表!I74=0,NA(),集計表!I74) -> 372 | H157: =IF(集計表!J74=0,NA(),集計表!J74) -> 382 | I157: =IF(集計表!K74=0,NA(),集計表!K74) -> 342 | ... AR157: =IF(集計表!AT74=0,NA(),集計表!AT74) -> #N/A
A158: 平均価格 | B158: =集計表!D75 -> 349 | C158: =集計表!E75 -> 349 | D158: =集計表!F75 -> 349 | E158: =集計表!G75 -> 349 | F158: =集計表!H75 -> 349 | G158: =集計表!I75 -> 349 | H158: =集計表!J75 -> 349 | I158: =集計表!K75 -> 330 | ... AR158: =集計表!AT75 -> 364
A159: 平年比 | B159: =IFERROR(B157/B158, "") -> 1.0744986 | C159: =IFERROR(C157/C158, "") -> 1.0888252 | D159: =IFERROR(D157/D158, "") -> 1.0687679 | E159: =IFERROR(E157/E158, "") -> 1.0401146 | F159: =IFERROR(F157/F158, "") -> 1.0659026 | G159: =IFERROR(G157/G158, "") -> 1.0659026 | H159: =IFERROR(H157/H158, "") -> 1.0945559 | I159: =IFERROR(I157/I158, "") -> 1.0363636 | ... AR159: =IFERROR(AR157/AR158, "")
A160: 資料：alic「ベジ探」、（原資料）農林水産省「青果物卸売市場調査（日別調査）結果」

Sheet ピーマン
A1: ４．「ピーマン」の卸売数量と価格の推移 | L1: =TEXT(集計表!$C$1,"(e.m/d～)") -> (8.6/1～)
A2: （東京都中央卸売市場）
A35: =集計表!C79 -> 46174 | B35: =集計表!D79 -> 6/1 | C35: =集計表!E79 -> 2 | D35: =集計表!F79 -> 4 | E35: =集計表!G79 -> 5 | F35: =集計表!H79 -> 6 | G35: =集計表!I79 -> 8 | H35: =集計表!J79 -> 9 | ... AR35: =集計表!AT79 -> 31
A36: 入荷量 | B36: =IF(集計表!D81="","",集計表!D81) -> 142.034 | C36: =IF(集計表!E81="","",集計表!E81) -> 96.356 | D36: =IF(集計表!F81="","",集計表!F81) -> 105.508 | E36: =IF(集計表!G81="","",集計表!G81) -> 90.334 | F36: =IF(集計表!H81="","",集計表!H81) -> 96.923 | G36: =IF(集計表!I81="","",集計表!I81) -> 170.557 | H36: =IF(集計表!J81="","",集計表!J81) -> 114.796 | I36: =IF(集計表!K81="","",集計表!K81) -> 160.191 | ... AR36: =IF(集計表!AT81="","",集計表!AT81)
A37: 卸売価格 | B37: =IF(集計表!D82=0,NA(),集計表!D82) -> 519 | C37: =IF(集計表!E82=0,NA(),集計表!E82) -> 516 | D37: =IF(集計表!F82=0,NA(),集計表!F82) -> 525 | E37: =IF(集計表!G82=0,NA(),集計表!G82) -> 480 | F37: =IF(集計表!H82=0,NA(),集計表!H82) -> 492 | G37: =IF(集計表!I82=0,NA(),集計表!I82) -> 459 | H37: =IF(集計表!J82=0,NA(),集計表!J82) -> 434 | I37: =IF(集計表!K82=0,NA(),集計表!K82) -> 434 | ... AR37: =IF(集計表!AT82=0,NA(),集計表!AT82) -> #N/A
A38: 平均価格 | B38: =集計表!D83 -> 464 | C38: =集計表!E83 -> 464 | D38: =集計表!F83 -> 464 | E38: =集計表!G83 -> 464 | F38: =集計表!H83 -> 464 | G38: =集計表!I83 -> 464 | H38: =集計表!J83 -> 464 | I38: =集計表!K83 -> 498 | ... AR38: =集計表!AT83 -> 460
A39: 平年比 | B39: =IFERROR(B37/B38, "") -> 1.1185345 | C39: =IFERROR(C37/C38, "") -> 1.112069 | D39: =IFERROR(D37/D38, "") -> 1.1314655 | E39: =IFERROR(E37/E38, "") -> 1.0344828 | F39: =IFERROR(F37/F38, "") -> 1.0603448 | G39: =IFERROR(G37/G38, "") -> 0.98922414 | H39: =IFERROR(H37/H38, "") -> 0.93534483 | I39: =IFERROR(I37/I38, "") -> 0.87148594 | ... AR39: =IFERROR(AR37/AR38, "")
A40: 資料：alic「ベジ探」、（原資料）農林水産省「青果物卸売市場調査（日別調査）結果」
A41: ４．「ピーマン」の卸売数量と価格の推移 | L41: =TEXT(集計表!$C$1,"(e.m/d～)") -> (8.6/1～)
A42: （名古屋市中央卸売市場）
A75: =集計表!C85 -> 46174 | B75: =集計表!D85 -> 6/1 | C75: =集計表!E85 -> 2 | D75: =集計表!F85 -> 4 | E75: =集計表!G85 -> 5 | F75: =集計表!H85 -> 6 | G75: =集計表!I85 -> 8 | H75: =集計表!J85 -> 9 | ... AR75: =集計表!AT85 -> 31
A76: 入荷量 | B76: =IF(集計表!D87="","",集計表!D87) -> 32.107 | C76: =IF(集計表!E87="","",集計表!E87) -> 21.479 | D76: =IF(集計表!F87="","",集計表!F87) -> 23.931 | E76: =IF(集計表!G87="","",集計表!G87) -> 14.159 | F76: =IF(集計表!H87="","",集計表!H87) -> 17.557 | G76: =IF(集計表!I87="","",集計表!I87) -> 31.734 | H76: =IF(集計表!J87="","",集計表!J87) -> 22.22 | I76: =IF(集計表!K87="","",集計表!K87) -> 27.156 | ... AR76: =IF(集計表!AT87="","",集計表!AT87)
A77: 卸売価格 | B77: =IF(集計表!D88=0,NA(),集計表!D88) -> 388 | C77: =IF(集計表!E88=0,NA(),集計表!E88) -> 421 | D77: =IF(集計表!F88=0,NA(),集計表!F88) -> 430 | E77: =IF(集計表!G88=0,NA(),集計表!G88) -> 531 | F77: =IF(集計表!H88=0,NA(),集計表!H88) -> 504 | G77: =IF(集計表!I88=0,NA(),集計表!I88) -> 379 | H77: =IF(集計表!J88=0,NA(),集計表!J88) -> 421 | I77: =IF(集計表!K88=0,NA(),集計表!K88) -> 404 | ... AR77: =IF(集計表!AT88=0,NA(),集計表!AT88) -> #N/A
A78: 平均価格 | B78: =集計表!D89 -> 420 | C78: =集計表!E89 -> 420 | D78: =集計表!F89 -> 420 | E78: =集計表!G89 -> 420 | F78: =集計表!H89 -> 420 | G78: =集計表!I89 -> 420 | H78: =集計表!J89 -> 420 | I78: =集計表!K89 -> 456 | ... AR78: =集計表!AT89 -> 468
A79: 平年比 | B79: =IFERROR(B77/B78, "") -> 0.92380952 | C79: =IFERROR(C77/C78, "") -> 1.002381 | D79: =IFERROR(D77/D78, "") -> 1.0238095 | E79: =IFERROR(E77/E78, "") -> 1.2642857 | F79: =IFERROR(F77/F78, "") -> 1.2 | G79: =IFERROR(G77/G78, "") -> 0.90238095 | H79: =IFERROR(H77/H78, "") -> 1.002381 | I79: =IFERROR(I77/I78, "") -> 0.88596491 | ... AR79: =IFERROR(AR77/AR78, "")
A80: 資料：alic「ベジ探」、（原資料）農林水産省「青果物卸売市場調査（日別調査）結果」
A81: ４．「ピーマン」の卸売数量と価格の推移 | L81: =TEXT(集計表!$C$1,"(e.m/d～)") -> (8.6/1～)
A82: （大阪市中央卸売市場）
A115: =集計表!C91 -> 46174 | B115: =集計表!D91 -> 6/1 | C115: =集計表!E91 -> 2 | D115: =集計表!F91 -> 4 | E115: =集計表!G91 -> 5 | F115: =集計表!H91 -> 6 | G115: =集計表!I91 -> 8 | H115: =集計表!J91 -> 9 | ... AR115: =集計表!AT91 -> 31
A116: 入荷量 | B116: =IF(集計表!D93="","",集計表!D93) -> 42.333 | C116: =IF(集計表!E93="","",集計表!E93) -> 31.61 | D116: =IF(集計表!F93="","",集計表!F93) -> 26.311 | E116: =IF(集計表!G93="","",集計表!G93) -> 27.863 | F116: =IF(集計表!H93="","",集計表!H93) -> 30.655 | G116: =IF(集計表!I93="","",集計表!I93) -> 43.154 | H116: =IF(集計表!J93="","",集計表!J93) -> 31.635 | I116: =IF(集計表!K93="","",集計表!K93) -> 45.91 | ... AR116: =IF(集計表!AT93="","",集計表!AT93)
A117: 卸売価格 | B117: =IF(集計表!D94=0,NA(),集計表!D94) -> 366 | C117: =IF(集計表!E94=0,NA(),集計表!E94) -> 345 | D117: =IF(集計表!F94=0,NA(),集計表!F94) -> 382 | E117: =IF(集計表!G94=0,NA(),集計表!G94) -> 376 | F117: =IF(集計表!H94=0,NA(),集計表!H94) -> 370 | G117: =IF(集計表!I94=0,NA(),集計表!I94) -> 335 | H117: =IF(集計表!J94=0,NA(),集計表!J94) -> 368 | I117: =IF(集計表!K94=0,NA(),集計表!K94) -> 350 | ... AR117: =IF(集計表!AT94=0,NA(),集計表!AT94) -> #N/A
A118: 平均価格 | B118: =集計表!D95 -> 378 | C118: =集計表!E95 -> 378 | D118: =集計表!F95 -> 378 | E118: =集計表!G95 -> 378 | F118: =集計表!H95 -> 378 | G118: =集計表!I95 -> 378 | H118: =集計表!J95 -> 378 | I118: =集計表!K95 -> 425 | ... AR118: =集計表!AT95 -> 417
A119: 平年比 | B119: =IFERROR(B117/B118, "") -> 0.96825397 | C119: =IFERROR(C117/C118, "") -> 0.91269841 | D119: =IFERROR(D117/D118, "") -> 1.010582 | E119: =IFERROR(E117/E118, "") -> 0.99470899 | F119: =IFERROR(F117/F118, "") -> 0.97883598 | G119: =IFERROR(G117/G118, "") -> 0.88624339 | H119: =IFERROR(H117/H118, "") -> 0.97354497 | I119: =IFERROR(I117/I118, "") -> 0.82352941 | ... AR119: =IFERROR(AR117/AR118, "")
A120: 資料：alic「ベジ探」、（原資料）農林水産省「青果物卸売市場調査（日別調査）結果」
A121: ４．「ピーマン」の卸売数量と価格の推移 | L121: =TEXT(集計表!$C$1,"(e.m/d～)") -> (8.6/1～)
A122: （福岡市中央卸売市場）
A155: =集計表!C97 -> 46174 | B155: =集計表!D97 -> 6/1 | C155: =集計表!E97 -> 2 | D155: =集計表!F97 -> 4 | E155: =集計表!G97 -> 5 | F155: =集計表!H97 -> 6 | G155: =集計表!I97 -> 8 | H155: =集計表!J97 -> 9 | ... AR155: =集計表!AT97 -> 31
A156: 入荷量 | B156: =IF(集計表!D99="","",集計表!D99) -> 18.631 | C156: =IF(集計表!E99="","",集計表!E99) -> 14.168 | D156: =IF(集計表!F99="","",集計表!F99) -> 26.322 | E156: =IF(集計表!G99="","",集計表!G99) -> 21.063 | F156: =IF(集計表!H99="","",集計表!H99) -> 25.589 | G156: =IF(集計表!I99="","",集計表!I99) -> 28.772 | H156: =IF(集計表!J99="","",集計表!J99) -> 34.015 | I156: =IF(集計表!K99="","",集計表!K99) -> 28.133 | ... AR156: =IF(集計表!AT99="","",集計表!AT99)
A157: 卸売価格 | B157: =IF(集計表!D100=0,NA(),集計表!D100) -> 359 | C157: =IF(集計表!E100=0,NA(),集計表!E100) -> 425 | D157: =IF(集計表!F100=0,NA(),集計表!F100) -> 434 | E157: =IF(集計表!G100=0,NA(),集計表!G100) -> 422 | F157: =IF(集計表!H100=0,NA(),集計表!H100) -> 331 | G157: =IF(集計表!I100=0,NA(),集計表!I100) -> 306 | H157: =IF(集計表!J100=0,NA(),集計表!J100) -> 301 | I157: =IF(集計表!K100=0,NA(),集計表!K100) -> 339 | ... AR157: =IF(集計表!AT100=0,NA(),集計表!AT100) -> #N/A
A158: 平均価格 | B158: =集計表!D101 -> 374 | C158: =集計表!E101 -> 374 | D158: =集計表!F101 -> 374 | E158: =集計表!G101 -> 374 | F158: =集計表!H101 -> 374 | G158: =集計表!I101 -> 374 | H158: =集計表!J101 -> 374 | I158: =集計表!K101 -> 384 | ... AR158: =集計表!AT101 -> 369
A159: 平年比 | B159: =IFERROR(B157/B158, "") -> 0.95989305 | C159: =IFERROR(C157/C158, "") -> 1.1363636 | D159: =IFERROR(D157/D158, "") -> 1.1604278 | E159: =IFERROR(E157/E158, "") -> 1.1283422 | F159: =IFERROR(F157/F158, "") -> 0.88502674 | G159: =IFERROR(G157/G158, "") -> 0.81818182 | H159: =IFERROR(H157/H158, "") -> 0.80481283 | I159: =IFERROR(I157/I158, "") -> 0.8828125 | ... AR159: =IFERROR(AR157/AR158, "")
A160: 資料：alic「ベジ探」、（原資料）農林水産省「青果物卸売市場調査（日別調査）結果」

Sheet 集計表
A1: きゅうり | B1: 東京都 | C1: 46174 | D1: 6/1 | E1: 2 | F1: 4 | G1: 5 | H1: 6 | I1: 8 | J1: 9 | K1: 11 | L1: 12 | M1: 13 | N1: 15 | O1: 16 | P1: 18 | Q1: 19 | R1: 20 | S1: 22 | T1: 23 | U1: 25 | V1: 26 | W1: 27 | X1: 29 | Y1: 30 | Z1: 7/2 | AA1: 3 | AB1: 4 | AC1: 6 | AD1: 7 | AE1: 9 | AF1: 10 | AG1: 11 | AH1: 13 | AI1: 14 | AJ1: 16 | AK1: 17 | AL1: 18 | AM1: 21 | AN1: 23 | AO1: 24 | AP1: 25 | AQ1: 27 | AR1: 28 | AS1: 30 | AT1: 31
C2: 入荷量 | D2: 364892 | E2: 215789 | F2: 331685 | G2: 178300 | H2: 158549 | I2: 269682 | J2: 185025 | K2: 300016 | L2: 151180 | M2: 173564 | N2: 311334 | O2: 188864 | P2: 326045 | Q2: 197383 | R2: 219442 | S2: 344893 | T2: 162637 | U2: 256746 | V2: 138205 | W2: 149230 | X2: 240300 | Y2: 141001 | Z2: 280601 | AA2: 141127 | AB2: 137452 | AC2: 214453 | AD2: 164296
C3: トン | D3: 364.892 | E3: 215.789 | F3: 331.685 | G3: 178.3 | H3: 158.549 | I3: 269.682 | J3: 185.025 | K3: 300.016 | L3: 151.18 | M3: 173.564 | N3: 311.334 | O3: 188.864 | P3: 326.045 | Q3: 197.383 | R3: 219.442 | S3: 344.893 | T3: 162.637 | U3: 256.746 | V3: 138.205 | W3: 149.23 | X3: 240.3 | Y3: 141.001 | Z3: 280.601 | AA3: 141.127 | AB3: 137.452 | AC3: 214.453 | AD3: 164.296
C4: 卸売価格 | D4: 255 | E4: 256 | F4: 254 | G4: 266 | H4: 295 | I4: 332 | J4: 347 | K4: 349 | L4: 353 | M4: 355 | N4: 362 | O4: 367 | P4: 372 | Q4: 375 | R4: 370 | S4: 367 | T4: 370 | U4: 366 | V4: 374 | W4: 376 | X4: 389 | Y4: 399 | Z4: 400 | AA4: 413 | AB4: 438 | AC4: 478 | AD4: 494
C5: 平均価格 | D5: 268 | E5: 268 | F5: 268 | G5: 268 | H5: 268 | I5: 268 | J5: 268 | K5: 261 | L5: 261 | M5: 261 | N5: 261 | O5: 261 | P5: 261 | Q5: 261 | R5: 261 | S5: 261 | T5: 261 | U5: 261 | V5: 261 | W5: 261 | X5: 261 | Y5: 261 | Z5: 287 | AA5: 287 | AB5: 287 | AC5: 287 | AD5: 287 | AE5: 287 | AF5: 287 | AG5: 314 | AH5: 314 | AI5: 314 | AJ5: 314 | AK5: 314 | AL5: 314 | AM5: 291 | AN5: 291 | AO5: 291 | AP5: 291 | AQ5: 291 | AR5: 291 | AS5: 291 | AT5: 291
A7: きゅうり | B7: 名古屋市 | C7: =$C$1 -> 46174 | D7: 6/1 | E7: 2 | F7: 4 | G7: 5 | H7: 6 | I7: 8 | J7: 9 | K7: 11 | L7: 12 | M7: 13 | N7: 15 | O7: 16 | P7: 18 | Q7: 19 | R7: 20 | S7: 22 | T7: 23 | U7: 25 | V7: 26 | W7: 27 | X7: 29 | Y7: 30 | Z7: 7/2 | AA7: 3 | AB7: 4 | AC7: 6 | AD7: 7 | AE7: 9 | AF7: 10 | AG7: 11 | AH7: 13 | AI7: 14 | AJ7: 16 | AK7: 17 | AL7: 18 | AM7: 21 | AN7: 23 | AO7: 24 | AP7: 25 | AQ7: 27 | AR7: 28 | AS7: 30 | AT7: 31
C8: 入荷量 | D8: 84773 | E8: 72381 | F8: 79922 | G8: 50750 | H8: 57715 | I8: 66613 | J8: 60658 | K8: 64840 | L8: 41430 | M8: 57105 | N8: 56422 | O8: 49656 | P8: 83948 | Q8: 51598 | R8: 49203 | S8: 89397 | T8: 49215 | U8: 75861 | V8: 40590 | W8: 47906 | X8: 53818 | Y8: 34881 | Z8: 63262 | AA8: 39116 | AB8: 36332 | AC8: 51672 | AD8: 36748
C9: トン | D9: 84.773 | E9: 72.381 | F9: 79.922 | G9: 50.75 | H9: 57.715 | I9: 66.613 | J9: 60.658 | K9: 64.84 | L9: 41.43 | M9: 57.105 | N9: 56.422 | O9: 49.656 | P9: 83.948 | Q9: 51.598 | R9: 49.203 | S9: 89.397 | T9: 49.215 | U9: 75.861 | V9: 40.59 | W9: 47.906 | X9: 53.818 | Y9: 34.881 | Z9: 63.262 | AA9: 39.116 | AB9: 36.332 | AC9: 51.672 | AD9: 36.748
C10: 卸売価格 | D10: 292 | E10: 278 | F10: 275 | G10: 289 | H10: 307 | I10: 310 | J10: 332 | K10: 312 | L10: 325 | M10: 310 | N10: 336 | O10: 353 | P10: 348 | Q10: 338 | R10: 360 | S10: 353 | T10: 334 | U10: 368 | V10: 358 | W10: 386 | X10: 394 | Y10: 426 | Z10: 404 | AA10: 412 | AB10: 421 | AC10: 438 | AD10: 449
C11: 平均価格 | D11: 269 | E11: 269 | F11: 269 | G11: 269 | H11: 269 | I11: 269 | J11: 269 | K11: 271 | L11: 271 | M11: 271 | N11: 271 | O11: 271 | P11: 271 | Q11: 271 | R11: 271 | S11: 275 | T11: 275 | U11: 275 | V11: 275 | W11: 275 | X11: 275 | Y11: 275 | Z11: 285 | AA11: 285 | AB11: 285 | AC11: 285 | AD11: 285 | AE11: 285 | AF11: 285 | AG11: 322 | AH11: 322 | AI11: 322 | AJ11: 322 | AK11: 322 | AL11: 322 | AM11: 308 | AN11: 308 | AO11: 308 | AP11: 308 | AQ11: 308 | AR11: 308 | AS11: 308 | AT11: 308
A13: きゅうり | B13: 大阪市 | C13: =$C$1 -> 46174 | D13: 6/1 | E13: 2 | F13: 4 | G13: 5 | H13: 6 | I13: 8 | J13: 9 | K13: 11 | L13: 12 | M13: 13 | N13: 15 | O13: 16 | P13: 18 | Q13: 19 | R13: 20 | S13: 22 | T13: 23 | U13: 25 | V13: 26 | W13: 27 | X13: 29 | Y13: 30 | Z13: 7/2 | AA13: 3 | AB13: 4 | AC13: 6 | AD13: 7 | AE13: 9 | AF13: 10 | AG13: 11 | AH13: 13 | AI13: 14 | AJ13: 16 | AK13: 17 | AL13: 18 | AM13: 21 | AN13: 23 | AO13: 24 | AP13: 25 | AQ13: 27 | AR13: 28 | AS13: 30 | AT13: 31
C14: 入荷量 | D14: 85244 | E14: 50196 | F14: 77613 | G14: 42025 | H14: 56294 | I14: 72800 | J14: 48997 | K14: 56929 | L14: 42701 | M14: 35561 | N14: 62147 | O14: 53110 | P14: 79213 | Q14: 46010 | R14: 54115 | S14: 77849 | T14: 52220 | U14: 67332 | V14: 54035 | W14: 38972 | X14: 70745 | Y14: 43777 | Z14: 83553 | AA14: 41194 | AB14: 41341 | AC14: 64294 | AD14: 45092
C15: トン | D15: 85.244 | E15: 50.196 | F15: 77.613 | G15: 42.025 | H15: 56.294 | I15: 72.8 | J15: 48.997 | K15: 56.929 | L15: 42.701 | M15: 35.561 | N15: 62.147 | O15: 53.11 | P15: 79.213 | Q15: 46.01 | R15: 54.115 | S15: 77.849 | T15: 52.22 | U15: 67.332 | V15: 54.035 | W15: 38.972 | X15: 70.745 | Y15: 43.777 | Z15: 83.553 | AA15: 41.194 | AB15: 41.341 | AC15: 64.294 | AD15: 45.092
C16: 卸売価格 | D16: 241 | E16: 256 | F16: 250 | G16: 278 | H16: 265 | I16: 295 | J16: 337 | K16: 324 | L16: 345 | M16: 351 | N16: 370 | O16: 390 | P16: 368 | Q16: 377 | R16: 379 | S16: 379 | T16: 362 | U16: 366 | V16: 382 | W16: 363 | X16: 402 | Y16: 375 | Z16: 396 | AA16: 406 | AB16: 433 | AC16: 454 | AD16: 477
C17: 平均価格 | D17: 252 | E17: 252 | F17: 252 | G17: 252 | H17: 252 | I17: 252 | J17: 252 | K17: 258 | L17: 258 | M17: 258 | N17: 258 | O17: 258 | P17: 258 | Q17: 258 | R17: 258 | S17: 266 | T17: 266 | U17: 266 | V17: 266 | W17: 266 | X17: 266 | Y17: 266 | Z17: 280 | AA17: 280 | AB17: 280 | AC17: 280 | AD17: 280 | AE17: 280 | AF17: 280 | AG17: 316 | AH17: 316 | AI17: 316 | AJ17: 316 | AK17: 316 | AL17: 316 | AM17: 298 | AN17: 298 | AO17: 298 | AP17: 298 | AQ17: 298 | AR17: 298 | AS17: 298 | AT17: 298
A19: きゅうり | B19: 福岡市 | C19: =$C$1 -> 46174 | D19: 6/1 | E19: 2 | F19: 4 | G19: 5 | H19: 6 | I19: 8 | J19: 9 | K19: 11 | L19: 12 | M19: 13 | N19: 15 | O19: 16 | P19: 18 | Q19: 19 | R19: 20 | S19: 22 | T19: 23 | U19: 25 | V19: 26 | W19: 27 | X19: 29 | Y19: 30 | Z19: 7/2 | AA19: 3 | AB19: 4 | AC19: 6 | AD19: 7 | AE19: 9 | AF19: 10 | AG19: 11 | AH19: 13 | AI19: 14 | AJ19: 16 | AK19: 17 | AL19: 18 | AM19: 21 | AN19: 23 | AO19: 24 | AP19: 25 | AQ19: 27 | AR19: 28 | AS19: 30 | AT19: 31
C20: 入荷量 | D20: 64113 | E20: 59839 | F20: 74663 | G20: 41733 | H20: 45334 | I20: 59483 | J20: 60132 | K20: 65485 | L20: 38595 | M20: 37481 | N20: 50825 | O20: 52823 | P20: 68974 | Q20: 51991 | R20: 51708 | S20: 60541 | T20: 53166 | U20: 43801 | V20: 30773 | W20: 26772 | X20: 24652 | Y20: 26210 | Z20: 39715 | AA20: 26248 | AB20: 29308 | AC20: 37174 | AD20: 42716
C21: トン | D21: 64.113 | E21: 59.839 | F21: 74.663 | G21: 41.733 | H21: 45.334 | I21: 59.483 | J21: 60.132 | K21: 65.485 | L21: 38.595 | M21: 37.481 | N21: 50.825 | O21: 52.823 | P21: 68.974 | Q21: 51.991 | R21: 51.708 | S21: 60.541 | T21: 53.166 | U21: 43.801 | V21: 30.773 | W21: 26.772 | X21: 24.652 | Y21: 26.21 | Z21: 39.715 | AA21: 26.248 | AB21: 29.308 | AC21: 37.174 | AD21: 42.716
C22: 卸売価格 | D22: 214 | E22: 227 | F22: 233 | G22: 247 | H22: 255 | I22: 277 | J22: 277 | K22: 294 | L22: 292 | M22: 343 | N22: 354 | O22: 360 | P22: 347 | Q22: 336 | R22: 327 | S22: 314 | T22: 314 | U22: 339 | V22: 347 | W22: 373 | X22: 394 | Y22: 399 | Z22: 421 | AA22: 428 | AB22: 464 | AC22: 489 | AD22: 499
C23: 平均価格 | D23: 214 | E23: 214 | F23: 214 | G23: 214 | H23: 214 | I23: 214 | J23: 214 | K23: 198 | L23: 198 | M23: 198 | N23: 198 | O23: 198 | P23: 198 | Q23: 198 | R23: 198 | S23: 201 | T23: 201 | U23: 201 | V23: 201 | W23: 201 | X23: 201 | Y23: 201 | Z23: 252 | AA23: 252 | AB23: 252 | AC23: 252 | AD23: 252 | AE23: 252 | AF23: 252 | AG23: 308 | AH23: 308 | AI23: 308 | AJ23: 308 | AK23: 308 | AL23: 308 | AM23: 303 | AN23: 303 | AO23: 303 | AP23: 303 | AQ23: 303 | AR23: 303 | AS23: 303 | AT23: 303
A27: トマト | B27: 東京都 | C27: =$C$1 -> 46174 | D27: 6/1 | E27: 2 | F27: 4 | G27: 5 | H27: 6 | I27: 8 | J27: 9 | K27: 11 | L27: 12 | M27: 13 | N27: 15 | O27: 16 | P27: 18 | Q27: 19 | R27: 20 | S27: 22 | T27: 23 | U27: 25 | V27: 26 | W27: 27 | X27: 29 | Y27: 30 | Z27: 7/2 | AA27: 3 | AB27: 4 | AC27: 6 | AD27: 7 | AE27: 9 | AF27: 10 | AG27: 11 | AH27: 13 | AI27: 14 | AJ27: 16 | AK27: 17 | AL27: 18 | AM27: 21 | AN27: 23 | AO27: 24 | AP27: 25 | AQ27: 27 | AR27: 28 | AS27: 30 | AT27: 31
C28: 入荷量 | D28: 309851 | E28: 201732 | F28: 371897 | G28: 199208 | H28: 286082 | I28: 357158 | J28: 229150 | K28: 347238 | L28: 172325 | M28: 196950 | N28: 254998 | O28: 183997 | P28: 307019 | Q28: 167138 | R28: 212113 | S28: 275617 | T28: 200644 | U28: 370715 | V28: 191357 | W28: 216975 | X28: 267434 | Y28: 185688 | Z28: 292095 | AA28: 158347 | AB28: 172562 | AC28: 255824 | AD28: 188036
C29: トン | D29: 309.851 | E29: 201.732 | F29: 371.897 | G29: 199.208 | H29: 286.082 | I29: 357.158 | J29: 229.15 | K29: 347.238 | L29: 172.325 | M29: 196.95 | N29: 254.998 | O29: 183.997 | P29: 307.019 | Q29: 167.138 | R29: 212.113 | S29: 275.617 | T29: 200.644 | U29: 370.715 | V29: 191.357 | W29: 216.975 | X29: 267.434 | Y29: 185.688 | Z29: 292.095 | AA29: 158.347 | AB29: 172.562 | AC29: 255.824 | AD29: 188.036
C30: 卸売価格 | D30: 390 | E30: 404 | F30: 402 | G30: 402 | H30: 417 | I30: 398 | J30: 403 | K30: 406 | L30: 409 | M30: 427 | N30: 412 | O30: 418 | P30: 430 | Q30: 429 | R30: 448 | S30: 442 | T30: 449 | U30: 441 | V30: 447 | W30: 451 | X30: 442 | Y30: 447 | Z30: 450 | AA30: 454 | AB30: 481 | AC30: 460 | AD30: 486
C31: 平均価格 | D31: 317 | E31: 317 | F31: 317 | G31: 317 | H31: 317 | I31: 317 | J31: 317 | K31: 351 | L31: 351 | M31: 351 | N31: 351 | O31: 351 | P31: 351 | Q31: 351 | R31: 351 | S31: 325 | T31: 325 | U31: 325 | V31: 325 | W31: 325 | X31: 325 | Y31: 325 | Z31: 353 | AA31: 353 | AB31: 353 | AC31: 353 | AD31: 353 | AE31: 353 | AF31: 353 | AG31: 366 | AH31: 366 | AI31: 366 | AJ31: 366 | AK31: 366 | AL31: 366 | AM31: 374 | AN31: 374 | AO31: 374 | AP31: 374 | AQ31: 374 | AR31: 374 | AS31: 374 | AT31: 374
A33: トマト | B33: 名古屋市 | C33: =$C$1 -> 46174 | D33: 6/1 | E33: 2 | F33: 4 | G33: 5 | H33: 6 | I33: 8 | J33: 9 | K33: 11 | L33: 12 | M33: 13 | N33: 15 | O33: 16 | P33: 18 | Q33: 19 | R33: 20 | S33: 22 | T33: 23 | U33: 25 | V33: 26 | W33: 27 | X33: 29 | Y33: 30 | Z33: 7/2 | AA33: 3 | AB33: 4 | AC33: 6 | AD33: 7 | AE33: 9 | AF33: 10 | AG33: 11 | AH33: 13 | AI33: 14 | AJ33: 16 | AK33: 17 | AL33: 18 | AM33: 21 | AN33: 23 | AO33: 24 | AP33: 25 | AQ33: 27 | AR33: 28 | AS33: 30 | AT33: 31
C34: 入荷量 | D34: 92629 | E34: 58246 | F34: 105395 | G34: 59839 | H34: 70196 | I34: 93370 | J34: 56257 | K34: 81138 | L34: 47032 | M34: 58368 | N34: 70993 | O34: 54740 | P34: 103652 | Q34: 48646 | R34: 58606 | S34: 70210 | T34: 61850 | U34: 88672 | V34: 40610 | W34: 52891 | X34: 48356 | Y34: 58238 | Z34: 49356 | AA34: 23661 | AB34: 43160 | AC34: 40402 | AD34: 50126
C35: トン | D35: 92.629 | E35: 58.246 | F35: 105.395 | G35: 59.839 | H35: 70.196 | I35: 93.37 | J35: 56.257 | K35: 81.138 | L35: 47.032 | M35: 58.368 | N35: 70.993 | O35: 54.74 | P35: 103.652 | Q35: 48.646 | R35: 58.606 | S35: 70.21 | T35: 61.85 | U35: 88.672 | V35: 40.61 | W35: 52.891 | X35: 48.356 | Y35: 58.238 | Z35: 49.356 | AA35: 23.661 | AB35: 43.16 | AC35: 40.402 | AD35: 50.126
C36: 卸売価格 | D36: 330 | E36: 337 | F36: 330 | G36: 335 | H36: 341 | I36: 333 | J36: 348 | K36: 343 | L36: 347 | M36: 357 | N36: 365 | O36: 418 | P36: 401 | Q36: 384 | R36: 393 | S36: 379 | T36: 412 | U36: 380 | V36: 380 | W36: 381 | X36: 394 | Y36: 427 | Z36: 410 | AA36: 433 | AB36: 430 | AC36: 452 | AD36: 463
C37: 平均価格 | D37: 269 | E37: 269 | F37: 269 | G37: 269 | H37: 269 | I37: 269 | J37: 269 | K37: 294 | L37: 294 | M37: 294 | N37: 294 | O37: 294 | P37: 294 | Q37: 294 | R37: 294 | S37: 284 | T37: 284 | U37: 284 | V37: 284 | W37: 284 | X37: 284 | Y37: 284 | Z37: 314 | AA37: 314 | AB37: 314 | AC37: 314 | AD37: 314 | AE37: 314 | AF37: 314 | AG37: 348 | AH37: 348 | AI37: 348 | AJ37: 348 | AK37: 348 | AL37: 348 | AM37: 367 | AN37: 367 | AO37: 367 | AP37: 367 | AQ37: 367 | AR37: 367 | AS37: 367 | AT37: 367
A39: トマト | B39: 大阪市 | C39: =$C$1 -> 46174 | D39: 6/1 | E39: 2 | F39: 4 | G39: 5 | H39: 6 | I39: 8 | J39: 9 | K39: 11 | L39: 12 | M39: 13 | N39: 15 | O39: 16 | P39: 18 | Q39: 19 | R39: 20 | S39: 22 | T39: 23 | U39: 25 | V39: 26 | W39: 27 | X39: 29 | Y39: 30 | Z39: 7/2 | AA39: 3 | AB39: 4 | AC39: 6 | AD39: 7 | AE39: 9 | AF39: 10 | AG39: 11 | AH39: 13 | AI39: 14 | AJ39: 16 | AK39: 17 | AL39: 18 | AM39: 21 | AN39: 23 | AO39: 24 | AP39: 25 | AQ39: 27 | AR39: 28 | AS39: 30 | AT39: 31
C40: 入荷量 | D40: 116022 | E40: 70417 | F40: 112553 | G40: 68597 | H40: 79708 | I40: 134476 | J40: 72179 | K40: 115647 | L40: 56641 | M40: 60517 | N40: 93706 | O40: 63065 | P40: 97733 | Q40: 67725 | R40: 57841 | S40: 104014 | T40: 75054 | U40: 97967 | V40: 52919 | W40: 54461 | X40: 88475 | Y40: 58764 | Z40: 80836 | AA40: 49109 | AB40: 54653 | AC40: 91622 | AD40: 51146
C41: トン | D41: 116.022 | E41: 70.417 | F41: 112.553 | G41: 68.597 | H41: 79.708 | I41: 134.476 | J41: 72.179 | K41: 115.647 | L41: 56.641 | M41: 60.517 | N41: 93.706 | O41: 63.065 | P41: 97.733 | Q41: 67.725 | R41: 57.841 | S41: 104.014 | T41: 75.054 | U41: 97.967 | V41: 52.919 | W41: 54.461 | X41: 88.475 | Y41: 58.764 | Z41: 80.836 | AA41: 49.109 | AB41: 54.653 | AC41: 91.622 | AD41: 51.146
C42: 卸売価格 | D42: 363 | E42: 374 | F42: 368 | G42: 368 | H42: 383 | I42: 363 | J42: 374 | K42: 367 | L42: 361 | M42: 379 | N42: 370 | O42: 390 | P42: 391 | Q42: 392 | R42: 404 | S42: 419 | T42: 433 | U42: 412 | V42: 401 | W42: 416 | X42: 395 | Y42: 420 | Z42: 409 | AA42: 428 | AB42: 446 | AC42: 436 | AD42: 449
C43: 平均価格 | D43: 311 | E43: 311 | F43: 311 | G43: 311 | H43: 311 | I43: 311 | J43: 311 | K43: 333 | L43: 333 | M43: 333 | N43: 333 | O43: 333 | P43: 333 | Q43: 333 | R43: 333 | S43: 335 | T43: 335 | U43: 335 | V43: 335 | W43: 335 | X43: 335 | Y43: 335 | Z43: 348 | AA43: 348 | AB43: 348 | AC43: 348 | AD43: 348 | AE43: 348 | AF43: 348 | AG43: 359 | AH43: 359 | AI43: 359 | AJ43: 359 | AK43: 359 | AL43: 359 | AM43: 361 | AN43: 361 | AO43: 361 | AP43: 361 | AQ43: 361 | AR43: 361 | AS43: 361 | AT43: 361
A45: トマト | B45: 福岡市 | C45: =$C$1 -> 46174 | D45: 6/1 | E45: 2 | F45: 4 | G45: 5 | H45: 6 | I45: 8 | J45: 9 | K45: 11 | L45: 12 | M45: 13 | N45: 15 | O45: 16 | P45: 18 | Q45: 19 | R45: 20 | S45: 22 | T45: 23 | U45: 25 | V45: 26 | W45: 27 | X45: 29 | Y45: 30 | Z45: 7/2 | AA45: 3 | AB45: 4 | AC45: 6 | AD45: 7 | AE45: 9 | AF45: 10 | AG45: 11 | AH45: 13 | AI45: 14 | AJ45: 16 | AK45: 17 | AL45: 18 | AM45: 21 | AN45: 23 | AO45: 24 | AP45: 25 | AQ45: 27 | AR45: 28 | AS45: 30 | AT45: 31
C46: 入荷量 | D46: 38659 | E46: 41556 | F46: 48404 | G46: 35673 | H46: 44640 | I46: 57393 | J46: 45831 | K46: 57936 | L46: 37175 | M46: 40595 | N46: 47200 | O46: 43091 | P46: 57351 | Q46: 32704 | R46: 35469 | S46: 52076 | T46: 46037 | U46: 61772 | V46: 38288 | W46: 41607 | X46: 48836 | Y46: 36671 | Z46: 54439 | AA46: 34226 | AB46: 51346 | AC46: 71062 | AD46: 52807
C47: トン | D47: 38.659 | E47: 41.556 | F47: 48.404 | G47: 35.673 | H47: 44.64 | I47: 57.393 | J47: 45.831 | K47: 57.936 | L47: 37.175 | M47: 40.595 | N47: 47.2 | O47: 43.091 | P47: 57.351 | Q47: 32.704 | R47: 35.469 | S47: 52.076 | T47: 46.037 | U47: 61.772 | V47: 38.288 | W47: 41.607 | X47: 48.836 | Y47: 36.671 | Z47: 54.439 | AA47: 34.226 | AB47: 51.346 | AC47: 71.062 | AD47: 52.807
C48: 卸売価格 | D48: 342 | E48: 342 | F48: 344 | G48: 351 | H48: 348 | I48: 325 | J48: 324 | K48: 319 | L48: 320 | M48: 334 | N48: 341 | O48: 357 | P48: 345 | Q48: 340 | R48: 360 | S48: 364 | T48: 356 | U48: 360 | V48: 347 | W48: 360 | X48: 367 | Y48: 357 | Z48: 377 | AA48: 382 | AB48: 385 | AC48: 378 | AD48: 376
C49: 平均価格 | D49: 260 | E49: 260 | F49: 260 | G49: 260 | H49: 260 | I49: 260 | J49: 260 | K49: 273 | L49: 273 | M49: 273 | N49: 273 | O49: 273 | P49: 273 | Q49: 273 | R49: 273 | S49: 238 | T49: 238 | U49: 238 | V49: 238 | W49: 238 | X49: 238 | Y49: 238 | Z49: 268 | AA49: 268 | AB49: 268 | AC49: 268 | AD49: 268 | AE49: 268 | AF49: 268 | AG49: 279 | AH49: 279 | AI49: 279 | AJ49: 279 | AK49: 279 | AL49: 279 | AM49: 292 | AN49: 292 | AO49: 292 | AP49: 292 | AQ49: 292 | AR49: 292 | AS49: 292 | AT49: 292
...
